[2024-10-26 08:48:48,876] {taskinstance.py:896} INFO - Dependencies all met for <TaskInstance: ETL_task.crawl_data 2024-10-26T00:00:00+00:00 [queued]>
[2024-10-26 08:48:48,887] {taskinstance.py:896} INFO - Dependencies all met for <TaskInstance: ETL_task.crawl_data 2024-10-26T00:00:00+00:00 [queued]>
[2024-10-26 08:48:48,887] {taskinstance.py:1087} INFO - 
--------------------------------------------------------------------------------
[2024-10-26 08:48:48,887] {taskinstance.py:1088} INFO - Starting attempt 1 of 2
[2024-10-26 08:48:48,887] {taskinstance.py:1089} INFO - 
--------------------------------------------------------------------------------
[2024-10-26 08:48:48,894] {taskinstance.py:1107} INFO - Executing <Task(PythonOperator): crawl_data> on 2024-10-26T00:00:00+00:00
[2024-10-26 08:48:48,898] {standard_task_runner.py:52} INFO - Started process 549 to run task
[2024-10-26 08:48:48,901] {standard_task_runner.py:76} INFO - Running: ['***', 'tasks', 'run', 'ETL_task', 'crawl_data', '2024-10-26T00:00:00+00:00', '--job-id', '2', '--pool', 'default_pool', '--raw', '--subdir', 'DAGS_FOLDER/ETL.py', '--cfg-path', '/tmp/tmpg5v1wskd', '--error-file', '/tmp/tmpxnsqqvp_']
[2024-10-26 08:48:48,902] {standard_task_runner.py:77} INFO - Job 2: Subtask crawl_data
[2024-10-26 08:48:48,943] {logging_mixin.py:104} INFO - Running <TaskInstance: ETL_task.crawl_data 2024-10-26T00:00:00+00:00 [running]> on host 7d29636866e6
[2024-10-26 08:48:48,995] {taskinstance.py:1302} INFO - Exporting the following env vars:
AIRFLOW_CTX_DAG_EMAIL=thanhdera@gmail.com
AIRFLOW_CTX_DAG_OWNER=***
AIRFLOW_CTX_DAG_ID=ETL_task
AIRFLOW_CTX_TASK_ID=crawl_data
AIRFLOW_CTX_EXECUTION_DATE=2024-10-26T00:00:00+00:00
AIRFLOW_CTX_DAG_RUN_ID=scheduled__2024-10-26T00:00:00+00:00
[2024-10-26 08:48:51,469] {local_task_job.py:77} ERROR - Received SIGTERM. Terminating subprocesses
[2024-10-26 08:48:51,475] {process_utils.py:100} INFO - Sending Signals.SIGTERM to GPID 549
[2024-10-26 08:48:51,476] {taskinstance.py:1284} ERROR - Received SIGTERM. Terminating subprocesses.
[2024-10-26 08:48:51,491] {taskinstance.py:1501} ERROR - Task failed with exception
Traceback (most recent call last):
  File "/home/airflow/.local/lib/python3.6/site-packages/airflow/models/taskinstance.py", line 1157, in _run_raw_task
    self._prepare_and_execute_task_with_callbacks(context, task)
  File "/home/airflow/.local/lib/python3.6/site-packages/airflow/models/taskinstance.py", line 1331, in _prepare_and_execute_task_with_callbacks
    result = self._execute_task(context, task_copy)
  File "/home/airflow/.local/lib/python3.6/site-packages/airflow/models/taskinstance.py", line 1361, in _execute_task
    result = task_copy.execute(context=context)
  File "/home/airflow/.local/lib/python3.6/site-packages/airflow/operators/python.py", line 150, in execute
    return_value = self.execute_callable()
  File "/home/airflow/.local/lib/python3.6/site-packages/airflow/operators/python.py", line 161, in execute_callable
    return self.python_callable(*self.op_args, **self.op_kwargs)
  File "/opt/airflow/dags/ETL.py", line 41, in crawl_and_store
    time.sleep(5)
  File "/home/airflow/.local/lib/python3.6/site-packages/airflow/models/taskinstance.py", line 1286, in signal_handler
    raise AirflowException("Task received SIGTERM signal")
airflow.exceptions.AirflowException: Task received SIGTERM signal
[2024-10-26 08:48:51,497] {taskinstance.py:1551} INFO - Marking task as UP_FOR_RETRY. dag_id=ETL_task, task_id=crawl_data, execution_date=20241026T000000, start_date=20241026T084848, end_date=20241026T084851
[2024-10-26 08:48:51,530] {logging_mixin.py:104} WARNING - /home/***/.local/lib/python3.6/site-packages/***/utils/email.py:102 PendingDeprecationWarning: Fetching SMTP credentials from configuration variables will be deprecated in a future release. Please set credentials using a connection instead.
[2024-10-26 08:48:51,530] {configuration.py:365} WARNING - section/key [smtp/smtp_user] not found in config
[2024-10-26 08:48:51,531] {email.py:208} INFO - Email alerting: attempt 1
[2024-10-26 08:48:51,541] {configuration.py:365} WARNING - section/key [smtp/smtp_user] not found in config
[2024-10-26 08:48:51,543] {email.py:208} INFO - Email alerting: attempt 1
[2024-10-26 08:48:51,544] {taskinstance.py:1557} ERROR - Failed to send email to: ['thanhdera@gmail.com']
Traceback (most recent call last):
  File "/home/airflow/.local/lib/python3.6/site-packages/airflow/models/taskinstance.py", line 1157, in _run_raw_task
    self._prepare_and_execute_task_with_callbacks(context, task)
  File "/home/airflow/.local/lib/python3.6/site-packages/airflow/models/taskinstance.py", line 1331, in _prepare_and_execute_task_with_callbacks
    result = self._execute_task(context, task_copy)
  File "/home/airflow/.local/lib/python3.6/site-packages/airflow/models/taskinstance.py", line 1361, in _execute_task
    result = task_copy.execute(context=context)
  File "/home/airflow/.local/lib/python3.6/site-packages/airflow/operators/python.py", line 150, in execute
    return_value = self.execute_callable()
  File "/home/airflow/.local/lib/python3.6/site-packages/airflow/operators/python.py", line 161, in execute_callable
    return self.python_callable(*self.op_args, **self.op_kwargs)
  File "/opt/airflow/dags/ETL.py", line 41, in crawl_and_store
    time.sleep(5)
  File "/home/airflow/.local/lib/python3.6/site-packages/airflow/models/taskinstance.py", line 1286, in signal_handler
    raise AirflowException("Task received SIGTERM signal")
airflow.exceptions.AirflowException: Task received SIGTERM signal

During handling of the above exception, another exception occurred:

Traceback (most recent call last):
  File "/home/airflow/.local/lib/python3.6/site-packages/airflow/models/taskinstance.py", line 1896, in email_alert
    send_email(self.task.email, subject, html_content)
  File "/home/airflow/.local/lib/python3.6/site-packages/airflow/utils/email.py", line 66, in send_email
    **kwargs,
  File "/home/airflow/.local/lib/python3.6/site-packages/airflow/utils/email.py", line 102, in send_email_smtp
    send_mime_email(e_from=smtp_mail_from, e_to=recipients, mime_msg=msg, conn_id=conn_id, dryrun=dryrun)
  File "/home/airflow/.local/lib/python3.6/site-packages/airflow/utils/email.py", line 210, in send_mime_email
    conn = _get_smtp_connection(smtp_host, smtp_port, smtp_timeout, smtp_ssl)
  File "/home/airflow/.local/lib/python3.6/site-packages/airflow/utils/email.py", line 244, in _get_smtp_connection
    else smtplib.SMTP(host=host, port=port, timeout=timeout)
  File "/usr/local/lib/python3.6/smtplib.py", line 251, in __init__
    (code, msg) = self.connect(host, port)
  File "/usr/local/lib/python3.6/smtplib.py", line 336, in connect
    self.sock = self._get_socket(host, port, self.timeout)
  File "/usr/local/lib/python3.6/smtplib.py", line 307, in _get_socket
    self.source_address)
  File "/usr/local/lib/python3.6/socket.py", line 724, in create_connection
    raise err
  File "/usr/local/lib/python3.6/socket.py", line 713, in create_connection
    sock.connect(sa)
OSError: [Errno 99] Cannot assign requested address

During handling of the above exception, another exception occurred:

Traceback (most recent call last):
  File "/home/airflow/.local/lib/python3.6/site-packages/airflow/models/taskinstance.py", line 1555, in handle_failure
    self.email_alert(error)
  File "/home/airflow/.local/lib/python3.6/site-packages/airflow/models/taskinstance.py", line 1898, in email_alert
    send_email(self.task.email, subject, html_content_err)
  File "/home/airflow/.local/lib/python3.6/site-packages/airflow/utils/email.py", line 66, in send_email
    **kwargs,
  File "/home/airflow/.local/lib/python3.6/site-packages/airflow/utils/email.py", line 102, in send_email_smtp
    send_mime_email(e_from=smtp_mail_from, e_to=recipients, mime_msg=msg, conn_id=conn_id, dryrun=dryrun)
  File "/home/airflow/.local/lib/python3.6/site-packages/airflow/utils/email.py", line 210, in send_mime_email
    conn = _get_smtp_connection(smtp_host, smtp_port, smtp_timeout, smtp_ssl)
  File "/home/airflow/.local/lib/python3.6/site-packages/airflow/utils/email.py", line 244, in _get_smtp_connection
    else smtplib.SMTP(host=host, port=port, timeout=timeout)
  File "/usr/local/lib/python3.6/smtplib.py", line 251, in __init__
    (code, msg) = self.connect(host, port)
  File "/usr/local/lib/python3.6/smtplib.py", line 336, in connect
    self.sock = self._get_socket(host, port, self.timeout)
  File "/usr/local/lib/python3.6/smtplib.py", line 307, in _get_socket
    self.source_address)
  File "/usr/local/lib/python3.6/socket.py", line 724, in create_connection
    raise err
  File "/usr/local/lib/python3.6/socket.py", line 713, in create_connection
    sock.connect(sa)
OSError: [Errno 99] Cannot assign requested address
[2024-10-26 08:48:51,611] {process_utils.py:66} INFO - Process psutil.Process(pid=549, status='terminated', exitcode=1, started='08:48:48') (549) terminated with exit code 1
[2024-10-26 08:52:29,897] {taskinstance.py:896} INFO - Dependencies all met for <TaskInstance: ETL_task.crawl_data 2024-10-26T00:00:00+00:00 [queued]>
[2024-10-26 08:52:29,911] {taskinstance.py:896} INFO - Dependencies all met for <TaskInstance: ETL_task.crawl_data 2024-10-26T00:00:00+00:00 [queued]>
[2024-10-26 08:52:29,911] {taskinstance.py:1087} INFO - 
--------------------------------------------------------------------------------
[2024-10-26 08:52:29,911] {taskinstance.py:1088} INFO - Starting attempt 1 of 2
[2024-10-26 08:52:29,912] {taskinstance.py:1089} INFO - 
--------------------------------------------------------------------------------
[2024-10-26 08:52:29,918] {taskinstance.py:1107} INFO - Executing <Task(PythonOperator): crawl_data> on 2024-10-26T00:00:00+00:00
[2024-10-26 08:52:29,922] {standard_task_runner.py:52} INFO - Started process 366 to run task
[2024-10-26 08:52:29,925] {standard_task_runner.py:76} INFO - Running: ['***', 'tasks', 'run', 'ETL_task', 'crawl_data', '2024-10-26T00:00:00+00:00', '--job-id', '5', '--pool', 'default_pool', '--raw', '--subdir', 'DAGS_FOLDER/ETL.py', '--cfg-path', '/tmp/tmpxhp5u2j_', '--error-file', '/tmp/tmpgeh3wqs7']
[2024-10-26 08:52:29,927] {standard_task_runner.py:77} INFO - Job 5: Subtask crawl_data
[2024-10-26 08:52:29,957] {logging_mixin.py:104} INFO - Running <TaskInstance: ETL_task.crawl_data 2024-10-26T00:00:00+00:00 [running]> on host ceff2ee9e0e7
[2024-10-26 08:52:29,989] {taskinstance.py:1302} INFO - Exporting the following env vars:
AIRFLOW_CTX_DAG_EMAIL=thanhdera@gmail.com
AIRFLOW_CTX_DAG_OWNER=***
AIRFLOW_CTX_DAG_ID=ETL_task
AIRFLOW_CTX_TASK_ID=crawl_data
AIRFLOW_CTX_EXECUTION_DATE=2024-10-26T00:00:00+00:00
AIRFLOW_CTX_DAG_RUN_ID=scheduled__2024-10-26T00:00:00+00:00
[2024-10-26 08:52:59,256] {taskinstance.py:1501} ERROR - Task failed with exception
Traceback (most recent call last):
  File "/home/airflow/.local/lib/python3.6/site-packages/airflow/models/taskinstance.py", line 1157, in _run_raw_task
    self._prepare_and_execute_task_with_callbacks(context, task)
  File "/home/airflow/.local/lib/python3.6/site-packages/airflow/models/taskinstance.py", line 1331, in _prepare_and_execute_task_with_callbacks
    result = self._execute_task(context, task_copy)
  File "/home/airflow/.local/lib/python3.6/site-packages/airflow/models/taskinstance.py", line 1361, in _execute_task
    result = task_copy.execute(context=context)
  File "/home/airflow/.local/lib/python3.6/site-packages/airflow/operators/python.py", line 150, in execute
    return_value = self.execute_callable()
  File "/home/airflow/.local/lib/python3.6/site-packages/airflow/operators/python.py", line 161, in execute_callable
    return self.python_callable(*self.op_args, **self.op_kwargs)
  File "/opt/airflow/dags/ETL.py", line 37, in crawl_and_store
    team_data = pd.read_html(data.text, match="Scores & Fixtures")[0]
  File "/home/airflow/.local/lib/python3.6/site-packages/pandas/util/_decorators.py", line 296, in wrapper
    return func(*args, **kwargs)
  File "/home/airflow/.local/lib/python3.6/site-packages/pandas/io/html.py", line 1101, in read_html
    displayed_only=displayed_only,
  File "/home/airflow/.local/lib/python3.6/site-packages/pandas/io/html.py", line 917, in _parse
    raise retained
  File "/home/airflow/.local/lib/python3.6/site-packages/pandas/io/html.py", line 898, in _parse
    tables = p.parse_tables()
  File "/home/airflow/.local/lib/python3.6/site-packages/pandas/io/html.py", line 217, in parse_tables
    tables = self._parse_tables(self._build_doc(), self.match, self.attrs)
  File "/home/airflow/.local/lib/python3.6/site-packages/pandas/io/html.py", line 547, in _parse_tables
    raise ValueError("No tables found")
ValueError: No tables found
[2024-10-26 08:52:59,258] {taskinstance.py:1551} INFO - Marking task as UP_FOR_RETRY. dag_id=ETL_task, task_id=crawl_data, execution_date=20241026T000000, start_date=20241026T085229, end_date=20241026T085259
[2024-10-26 08:52:59,287] {logging_mixin.py:104} WARNING - /home/***/.local/lib/python3.6/site-packages/***/utils/email.py:102 PendingDeprecationWarning: Fetching SMTP credentials from configuration variables will be deprecated in a future release. Please set credentials using a connection instead.
[2024-10-26 08:52:59,287] {configuration.py:365} WARNING - section/key [smtp/smtp_user] not found in config
[2024-10-26 08:52:59,287] {email.py:208} INFO - Email alerting: attempt 1
[2024-10-26 08:52:59,297] {configuration.py:365} WARNING - section/key [smtp/smtp_user] not found in config
[2024-10-26 08:52:59,297] {email.py:208} INFO - Email alerting: attempt 1
[2024-10-26 08:52:59,298] {taskinstance.py:1557} ERROR - Failed to send email to: ['thanhdera@gmail.com']
Traceback (most recent call last):
  File "/home/airflow/.local/lib/python3.6/site-packages/airflow/models/taskinstance.py", line 1157, in _run_raw_task
    self._prepare_and_execute_task_with_callbacks(context, task)
  File "/home/airflow/.local/lib/python3.6/site-packages/airflow/models/taskinstance.py", line 1331, in _prepare_and_execute_task_with_callbacks
    result = self._execute_task(context, task_copy)
  File "/home/airflow/.local/lib/python3.6/site-packages/airflow/models/taskinstance.py", line 1361, in _execute_task
    result = task_copy.execute(context=context)
  File "/home/airflow/.local/lib/python3.6/site-packages/airflow/operators/python.py", line 150, in execute
    return_value = self.execute_callable()
  File "/home/airflow/.local/lib/python3.6/site-packages/airflow/operators/python.py", line 161, in execute_callable
    return self.python_callable(*self.op_args, **self.op_kwargs)
  File "/opt/airflow/dags/ETL.py", line 37, in crawl_and_store
    team_data = pd.read_html(data.text, match="Scores & Fixtures")[0]
  File "/home/airflow/.local/lib/python3.6/site-packages/pandas/util/_decorators.py", line 296, in wrapper
    return func(*args, **kwargs)
  File "/home/airflow/.local/lib/python3.6/site-packages/pandas/io/html.py", line 1101, in read_html
    displayed_only=displayed_only,
  File "/home/airflow/.local/lib/python3.6/site-packages/pandas/io/html.py", line 917, in _parse
    raise retained
  File "/home/airflow/.local/lib/python3.6/site-packages/pandas/io/html.py", line 898, in _parse
    tables = p.parse_tables()
  File "/home/airflow/.local/lib/python3.6/site-packages/pandas/io/html.py", line 217, in parse_tables
    tables = self._parse_tables(self._build_doc(), self.match, self.attrs)
  File "/home/airflow/.local/lib/python3.6/site-packages/pandas/io/html.py", line 547, in _parse_tables
    raise ValueError("No tables found")
ValueError: No tables found

During handling of the above exception, another exception occurred:

Traceback (most recent call last):
  File "/home/airflow/.local/lib/python3.6/site-packages/airflow/models/taskinstance.py", line 1896, in email_alert
    send_email(self.task.email, subject, html_content)
  File "/home/airflow/.local/lib/python3.6/site-packages/airflow/utils/email.py", line 66, in send_email
    **kwargs,
  File "/home/airflow/.local/lib/python3.6/site-packages/airflow/utils/email.py", line 102, in send_email_smtp
    send_mime_email(e_from=smtp_mail_from, e_to=recipients, mime_msg=msg, conn_id=conn_id, dryrun=dryrun)
  File "/home/airflow/.local/lib/python3.6/site-packages/airflow/utils/email.py", line 210, in send_mime_email
    conn = _get_smtp_connection(smtp_host, smtp_port, smtp_timeout, smtp_ssl)
  File "/home/airflow/.local/lib/python3.6/site-packages/airflow/utils/email.py", line 244, in _get_smtp_connection
    else smtplib.SMTP(host=host, port=port, timeout=timeout)
  File "/usr/local/lib/python3.6/smtplib.py", line 251, in __init__
    (code, msg) = self.connect(host, port)
  File "/usr/local/lib/python3.6/smtplib.py", line 336, in connect
    self.sock = self._get_socket(host, port, self.timeout)
  File "/usr/local/lib/python3.6/smtplib.py", line 307, in _get_socket
    self.source_address)
  File "/usr/local/lib/python3.6/socket.py", line 724, in create_connection
    raise err
  File "/usr/local/lib/python3.6/socket.py", line 713, in create_connection
    sock.connect(sa)
OSError: [Errno 99] Cannot assign requested address

During handling of the above exception, another exception occurred:

Traceback (most recent call last):
  File "/home/airflow/.local/lib/python3.6/site-packages/airflow/models/taskinstance.py", line 1555, in handle_failure
    self.email_alert(error)
  File "/home/airflow/.local/lib/python3.6/site-packages/airflow/models/taskinstance.py", line 1898, in email_alert
    send_email(self.task.email, subject, html_content_err)
  File "/home/airflow/.local/lib/python3.6/site-packages/airflow/utils/email.py", line 66, in send_email
    **kwargs,
  File "/home/airflow/.local/lib/python3.6/site-packages/airflow/utils/email.py", line 102, in send_email_smtp
    send_mime_email(e_from=smtp_mail_from, e_to=recipients, mime_msg=msg, conn_id=conn_id, dryrun=dryrun)
  File "/home/airflow/.local/lib/python3.6/site-packages/airflow/utils/email.py", line 210, in send_mime_email
    conn = _get_smtp_connection(smtp_host, smtp_port, smtp_timeout, smtp_ssl)
  File "/home/airflow/.local/lib/python3.6/site-packages/airflow/utils/email.py", line 244, in _get_smtp_connection
    else smtplib.SMTP(host=host, port=port, timeout=timeout)
  File "/usr/local/lib/python3.6/smtplib.py", line 251, in __init__
    (code, msg) = self.connect(host, port)
  File "/usr/local/lib/python3.6/smtplib.py", line 336, in connect
    self.sock = self._get_socket(host, port, self.timeout)
  File "/usr/local/lib/python3.6/smtplib.py", line 307, in _get_socket
    self.source_address)
  File "/usr/local/lib/python3.6/socket.py", line 724, in create_connection
    raise err
  File "/usr/local/lib/python3.6/socket.py", line 713, in create_connection
    sock.connect(sa)
OSError: [Errno 99] Cannot assign requested address
[2024-10-26 08:52:59,332] {local_task_job.py:149} INFO - Task exited with return code 1
